<?xml version="1.0" ?>
<sdf version="1.5">
  <model name="wheeltec_diff">
    <link name="base_link">
      <pose>0 0 0.16 0 0 0</pose>
      <inertial>
        <mass>2</mass>
        <inertia>
          <ixx>0.028819942</ixx>
          <iyy>0.047333716</iyy>
          <izz>0.054201740</izz>
          <ixy>0</ixy>
          <ixz>0</ixz>
          <iyz>0</iyz>
        </inertia>
      </inertial>
      <collision name="collision">
        <pose>0 0 0 0 0 0</pose>
        <geometry>
          <box>
            <size>0.25 0.15 0.1</size>
          </box>
        </geometry>
      </collision>
      <visual name="visual">
        <pose>0.045 0 -0.05 1.57 0 0</pose>
        <geometry>
          <mesh>
            <uri>model://wheeltec/meshes/body.dae</uri>
          </mesh>
        </geometry>
      </visual>
    </link>

    <link name="right_front_wheel">
      <pose>0.08 -0.1 0.12 1.57 0 0</pose>
      <inertial>
        <mass>0.3844</mass>
        <inertia>
          <ixx>0.000480000</ixx>
          <iyy>0.000480000</iyy>
          <izz>0.000480000</izz>
          <ixy>0</ixy>
          <ixz>0</ixz>
          <iyz>0</iyz>
        </inertia>
      </inertial>
      <collision name='right_front_wheel_collision'>
        <pose>0 0 0 0 0 0</pose>
        <geometry>
          <cylinder>
            <length>0.02</length>
            <radius>0.035</radius>
          </cylinder>
        </geometry>
        <surface>
          <friction>
            <ode>
              <mu>1.5</mu>
              <mu2>1.5</mu2>
              <slip1>0.0</slip1>
              <slip2>0.0</slip2>
            </ode>
          </friction>
          <contact>
            <ode>
              <min_depth>0.001</min_depth>
            </ode>
          </contact>
        </surface>
      </collision>
      <visual name="visual">
        <pose>-0.035 0.015 -0.1 3.14 0 0</pose>
        <geometry>
          <mesh>
            <uri>model://wheeltec/meshes/front.dae</uri>
          </mesh>
        </geometry>
      </visual>
    </link>

    <link name="right_after_wheel">
      <pose>-0.08 -0.1 0.12 1.57 0 0</pose>
      <inertial>
        <mass>0.3844</mass>
        <inertia>
          <ixx>0.000480000</ixx>
          <iyy>0.000480000</iyy>
          <izz>0.000480000</izz>
          <ixy>0</ixy>
          <ixz>0</ixz>
          <iyz>0</iyz>
        </inertia>
      </inertial>
      <collision name='right_after_wheel_collision'>
        <pose>0 0 0 0 0 0</pose>
        <geometry>
          <cylinder>
            <length>0.02</length>
            <radius>0.035</radius>
          </cylinder>
        </geometry>
        <surface>
          <friction>
            <ode>
              <mu>1.5</mu>
              <mu2>1.5</mu2>
              <slip1>0.0</slip1>
              <slip2>0.0</slip2>
            </ode>
          </friction>
          <contact>
            <ode>
              <min_depth>0.001</min_depth>
            </ode>
          </contact>
        </surface>
      </collision>
      <visual name="visual">
        <pose>-0.035 0.015 -0.1 3.14 0 0</pose>
        <geometry>
          <mesh>
            <uri>model://wheeltec/meshes/front.dae</uri>
          </mesh>
        </geometry>
      </visual>
    </link>


    <link name="left_front_wheel">
      <pose>0.08 0.1 0.12 1.57 0 0</pose>
      <inertial>
        <mass>0.3844</mass>
        <inertia>
          <ixx>0.000480000</ixx>
          <iyy>0.000480000</iyy>
          <izz>0.000480000</izz>
          <ixy>0</ixy>
          <ixz>0</ixz>
          <iyz>0</iyz>
        </inertia>
      </inertial>
      <collision name='left_front_wheel_collision'>
        <pose>0 0 0 0 0 0</pose>
        <geometry>
          <cylinder>
            <length>0.02</length>
            <radius>0.035</radius>
          </cylinder>
        </geometry>
        <surface>
          <friction>
            <ode>
              <mu>1.5</mu>
              <mu2>1.5</mu2>
              <slip1>0.0</slip1>
              <slip2>0.0</slip2>
            </ode>
          </friction>
          <contact>
            <ode>
              <min_depth>0.001</min_depth>
            </ode>
          </contact>
        </surface>
      </collision>
      <visual name="visual">
        <pose>-0.035 -0.015 0.1 0 0 0</pose>
        <geometry>
          <mesh>
            <uri>model://wheeltec/meshes/front.dae</uri>
          </mesh>
        </geometry>
      </visual>
    </link>

    <link name="left_after_wheel">
      <pose>-0.08 0.1 0.12 1.57 0 0</pose>
      <inertial>
        <mass>0.3844</mass>
        <inertia>
          <ixx>0.000480000</ixx>
          <iyy>0.000480000</iyy>
          <izz>0.000480000</izz>
          <ixy>0</ixy>
          <ixz>0</ixz>
          <iyz>0</iyz>
        </inertia>
      </inertial>
      <collision name='left_after_wheel_collision'>
        <pose>0 0 0 0 0 0</pose>
        <geometry>
          <cylinder>
            <length>0.02</length>
            <radius>0.035</radius>
          </cylinder>
        </geometry>
        <surface>
          <friction>
            <ode>
              <mu>1.5</mu>
              <mu2>1.5</mu2>
              <slip1>0.0</slip1>
              <slip2>0.0</slip2>
            </ode>
          </friction>
          <contact>
            <ode>
              <min_depth>0.001</min_depth>
            </ode>
          </contact>
        </surface>
      </collision>
      <visual name="visual">
        <pose>-0.035 -0.015 0.1 0 0 0</pose>
        <geometry>
          <mesh>
            <uri>model://wheeltec/meshes/front.dae</uri>
          </mesh>
        </geometry>
      </visual>
    </link>

    <joint type="revolute" name="right_front_wheel_joint">
      <child>right_front_wheel</child>
      <parent>base_link</parent>
      <axis>
        <xyz>0 1 0</xyz>
        <limit>
          <lower>-1e+16</lower>
          <upper>1e+16</upper>
        </limit>
        <dynamics>
          <spring_reference>0</spring_reference>
          <spring_stiffness>0</spring_stiffness>
        </dynamics>
        <use_parent_model_frame>1</use_parent_model_frame>
      </axis>
    </joint>

    <joint type="revolute" name="right_after_wheel_joint">
      <child>right_after_wheel</child>
      <parent>base_link</parent>
      <axis>
        <xyz>0 1 0</xyz>
        <limit>
          <lower>-1e+16</lower>
          <upper>1e+16</upper>
        </limit>
        <dynamics>
          <spring_reference>0</spring_reference>
          <spring_stiffness>0</spring_stiffness>
        </dynamics>
        <use_parent_model_frame>1</use_parent_model_frame>
      </axis>
    </joint>

    <joint type="revolute" name="left_front_wheel_joint">
      <child>left_front_wheel</child>
      <parent>base_link</parent>
      <axis>
        <xyz>0 1 0</xyz>
        <limit>
          <lower>-1e+16</lower>
          <upper>1e+16</upper>
        </limit>
        <dynamics>
          <spring_reference>0</spring_reference>
          <spring_stiffness>0</spring_stiffness>
        </dynamics>
        <use_parent_model_frame>1</use_parent_model_frame>
      </axis>
    </joint>

    <joint type="revolute" name="left_after_wheel_joint">
      <child>left_after_wheel</child>
      <parent>base_link</parent>
      <axis>
        <xyz>0 1 0</xyz>
        <limit>
          <lower>-1e+16</lower>
          <upper>1e+16</upper>
        </limit>
        <dynamics>
          <spring_reference>0</spring_reference>
          <spring_stiffness>0</spring_stiffness>
        </dynamics>
        <use_parent_model_frame>1</use_parent_model_frame>
      </axis>
    </joint>

    <plugin name="skid_steer_drive_controller" filename="libgazebo_ros_skid_steer_drive.so">
      <updateRate>100.0</updateRate>
      <alwaysOn>true</alwaysOn>
      <leftFrontJoint>left_front_wheel_joint</leftFrontJoint>
      <rightFrontJoint>right_front_wheel_joint</rightFrontJoint>
      <leftRearJoint>left_after_wheel_joint</leftRearJoint>
      <rightRearJoint>right_after_wheel_joint</rightRearJoint>
      <wheelSeparation>0.100</wheelSeparation>
      <wheelDiameter>0.07</wheelDiameter>
      <torque>20</torque>
      <commandTopic>cmd_vel</commandTopic>
      <odometryTopic>odom</odometryTopic>
      <odometryFrame>world</odometryFrame>
      <robotBaseFrame>base_link</robotBaseFrame>
      <broadcastTF>0</broadcastTF>
    </plugin>

  </model>
</sdf>
